Workbook
Name data_range: OFFSET([1]data!$A$2, 0, 0, [1]calculation!$B$1, [1]calculation!$B$2)
Name data_range: OFFSET(data!$A$2, 0, 0, calculation!$B$1, calculation!$B$2)
Name figure1_home: OFFSET('[1]Figure 1 Background Data'!$C$8, 0, 0, [1]calculation!$B$7, 1)
Name figure1_hospital: OFFSET('[1]Figure 1 Background Data'!$D$8, 0, 0, [1]calculation!$B$7, 1)
Name figure1_year: OFFSET('[1]Figure 1 Background Data'!$B$8, 0, 0, [1]calculation!$B$7, 1)
Name figurea11percent: OFFSET('Figure A1-1 - HB'!$N$8, 0,0, 1, COUNTA('Figure A1-1 - HB'!$8:$8)-1)
Name figurea11year: OFFSET('Figure A1-1 - HB'!$N$7, 0, 0, 1, COUNTA('Figure A1-1 - HB'!$7:$7))
Name figurea12percent: OFFSET('Figure A1-2 - HSCP'!$N$8, 0,0, 1, COUNTA('Figure A1-2 - HSCP'!$8:$8)-1)
Name figurea12year: OFFSET('Figure A1-2 - HSCP'!$N$7, 0, 0, 1, COUNTA('Figure A1-2 - HSCP'!$7:$7))
Name figurea13percent: OFFSET('Figure A1-3 - Deprivation'!$N$8, 0,0, 1, COUNTA('Figure A1-3 - Deprivation'!$8:$8)-1)
Name figurea13year: OFFSET('Figure A1-3 - Deprivation'!$N$7, 0, 0, 1, COUNTA('Figure A1-3 - Deprivation'!$7:$7))
Name figurea14percent: OFFSET('Figure A1-4 - Urban Rural'!$N$8, 0,0, 1, COUNTA('Figure A1-4 - Urban Rural'!$8:$8)-1)
Name figurea14year: OFFSET('Figure A1-4 - Urban Rural'!$N$7, 0, 0, 1, COUNTA('Figure A1-4 - Urban Rural'!$7:$7))
Name fy_max: OFFSET('[1]Figure 1 Background Data'!$A$7, [1]calculation!$B$7, 0, 1, 1)
Name fy_max: calculation!$K$9
Name fy_range: OFFSET([1]data!$B$2, 0, 0, [1]calculation!$B$1, 1)
Name fy_range: OFFSET(data!$B$2, 0, 0, calculation!$B$1, 1)

Sheet Notes
B1: =""
B2: Quality Outcome Measure 10: Percentage of time in the last 6 months of life spent at home or in a community setting
B4: Please read the notes below before looking at the data.
B6: Table 1: Percentage of time in the last six months of life spent at home or in a community setting; by NHS Board of Residence
B7: Table 2: Percentage of time in the last six months of life spent at home or in a community setting; by Health and Social Care Partnership
B8: Table 3: Percentage of time in the last six months of life spent at home or in a community setting; by Age and Sex
B9: Table 4: Percentage of time in the last six months of life spent at home or in a community setting; by Deprivation Category
B10: Table 5: Percentage of time in the last six months of life spent at home or in a community setting; by Urban/Rural Classification
B11: Table 6: Percentage of time in the last six months of life spent at home or in a community setting; by Local Authority
B13: Source: SMR01 - Acute Inpatient and Day Case, SMR01 Geriatric Long Stay (GLS), SMR04 - Mental Health Inpatient and Day Case, National Records of Scotland (NRS) death records
B14: Health and Social Care Team, PHS
B16: Measure notes
B18: p. | C18: =calculation!$E$15 -> #REF!
C19: See Appendix 2 of the full report for more information.
B21: 1. | C21: The length of hospital stays in 2020/21 and 2021/22 are likely to have been impacted by measures in place at different stages of the COVID-19 pandemic. This may be an underlying reason for the larger increase in the percentage of time spent at home or in a community setting between 2019/20 and 2020/21.
B23: 2. | C23: This measure has been calculated by subtracting the number of bed days spent in an acute, mental health or geriatric long stay hospital in the 6 months prior to death from the maximum number of bed days someone could have spent in hospital in the 6 months prior to death (182.5 days).
B43: 3. | C43: Number of bed days includes both elective and emergency admissions.
B45: 4. | C45: People who died where an external cause of death is coded on the death record have been excluded from the analysis.
C46: For full details of the external causes of death which have been omitted, please click here.
C47: Please note that people who died where a fall is coded on the death record are included within the cohort; W00-W19 Falls
B49: 5. | C49: NHS Board, Health and Social Care Partnership and Local Authority relate to location of residence at time of death. NHS Board figures are based on the 2019 boundaries.
B51: 6. | C51: These statistics are derived from data collected on discharges from acute and community hospitals (SMR01), pyschiatric hospitals (SMR04) and geriatric long stay facilities (SMR01 GLS) in Scotland.

Sheet Table 1 - HB
B1: =Notes!B1:O1
B2: Table 1: Percentage of last six months of life spent at home or in a community setting
B3: by NHS Board of Residence
L5: Financial Year Ending 31st March
B7: NHS Board of Residence | C7: =calculation!B$10 -> #REF! | D7: =calculation!C$10 -> #REF! | E7: =calculation!D$10 -> #REF! | F7: =calculation!E$10 -> #REF! | G7: =calculation!F$10 -> #REF! | H7: =calculation!G$10 -> #REF! | I7: =calculation!H$10 -> #REF! | J7: =calculation!I$10 -> #REF! | ... L7: =calculation!K$10 -> #REF!
B8: Ayrshire and Arran | C8: =VLOOKUP(CONCATENATE(LEFT(C$7, 7), "hb", "NHS ", $B8), [0]!data_range, 5, FALSE) -> #REF! | D8: =VLOOKUP(CONCATENATE(LEFT(D$7, 7), "hb", "NHS ", $B8), [0]!data_range, 5, FALSE) -> #REF! | E8: =VLOOKUP(CONCATENATE(LEFT(E$7, 7), "hb", "NHS ", $B8), [0]!data_range, 5, FALSE) -> #REF! | F8: =VLOOKUP(CONCATENATE(LEFT(F$7, 7), "hb", "NHS ", $B8), [0]!data_range, 5, FALSE) -> #REF! | G8: =VLOOKUP(CONCATENATE(LEFT(G$7, 7), "hb", "NHS ", $B8), [0]!data_range, 5, FALSE) -> #REF! | H8: =VLOOKUP(CONCATENATE(LEFT(H$7, 7), "hb", "NHS ", $B8), [0]!data_range, 5, FALSE) -> #REF! | I8: =VLOOKUP(CONCATENATE(LEFT(I$7, 7), "hb", "NHS ", $B8), [0]!data_range, 5, FALSE) -> #REF! | J8: =VLOOKUP(CONCATENATE(LEFT(J$7, 7), "hb", "NHS ", $B8), [0]!data_range, 5, FALSE) -> #REF! | ... L8: =VLOOKUP(CONCATENATE(LEFT(L$7, 7), "hb", "NHS ", $B8), [0]!data_range, 5, FALSE) -> #REF!
B9: Borders | C9: =VLOOKUP(CONCATENATE(LEFT(C$7, 7), "hb", "NHS ", $B9), [0]!data_range, 5, FALSE) -> #REF! | D9: =VLOOKUP(CONCATENATE(LEFT(D$7, 7), "hb", "NHS ", $B9), [0]!data_range, 5, FALSE) -> #REF! | E9: =VLOOKUP(CONCATENATE(LEFT(E$7, 7), "hb", "NHS ", $B9), [0]!data_range, 5, FALSE) -> #REF! | F9: =VLOOKUP(CONCATENATE(LEFT(F$7, 7), "hb", "NHS ", $B9), [0]!data_range, 5, FALSE) -> #REF! | G9: =VLOOKUP(CONCATENATE(LEFT(G$7, 7), "hb", "NHS ", $B9), [0]!data_range, 5, FALSE) -> #REF! | H9: =VLOOKUP(CONCATENATE(LEFT(H$7, 7), "hb", "NHS ", $B9), [0]!data_range, 5, FALSE) -> #REF! | I9: =VLOOKUP(CONCATENATE(LEFT(I$7, 7), "hb", "NHS ", $B9), [0]!data_range, 5, FALSE) -> #REF! | J9: =VLOOKUP(CONCATENATE(LEFT(J$7, 7), "hb", "NHS ", $B9), [0]!data_range, 5, FALSE) -> #REF! | ... L9: =VLOOKUP(CONCATENATE(LEFT(L$7, 7), "hb", "NHS ", $B9), [0]!data_range, 5, FALSE) -> #REF!
B10: Dumfries and Galloway | C10: =VLOOKUP(CONCATENATE(LEFT(C$7, 7), "hb", "NHS ", $B10), [0]!data_range, 5, FALSE) -> #REF! | D10: =VLOOKUP(CONCATENATE(LEFT(D$7, 7), "hb", "NHS ", $B10), [0]!data_range, 5, FALSE) -> #REF! | E10: =VLOOKUP(CONCATENATE(LEFT(E$7, 7), "hb", "NHS ", $B10), [0]!data_range, 5, FALSE) -> #REF! | F10: =VLOOKUP(CONCATENATE(LEFT(F$7, 7), "hb", "NHS ", $B10), [0]!data_range, 5, FALSE) -> #REF! | G10: =VLOOKUP(CONCATENATE(LEFT(G$7, 7), "hb", "NHS ", $B10), [0]!data_range, 5, FALSE) -> #REF! | H10: =VLOOKUP(CONCATENATE(LEFT(H$7, 7), "hb", "NHS ", $B10), [0]!data_range, 5, FALSE) -> #REF! | I10: =VLOOKUP(CONCATENATE(LEFT(I$7, 7), "hb", "NHS ", $B10), [0]!data_range, 5, FALSE) -> #REF! | J10: =VLOOKUP(CONCATENATE(LEFT(J$7, 7), "hb", "NHS ", $B10), [0]!data_range, 5, FALSE) -> #REF! | ... L10: =VLOOKUP(CONCATENATE(LEFT(L$7, 7), "hb", "NHS ", $B10), [0]!data_range, 5, FALSE) -> #REF!
B11: Fife | C11: =VLOOKUP(CONCATENATE(LEFT(C$7, 7), "hb", "NHS ", $B11), [0]!data_range, 5, FALSE) -> #REF! | D11: =VLOOKUP(CONCATENATE(LEFT(D$7, 7), "hb", "NHS ", $B11), [0]!data_range, 5, FALSE) -> #REF! | E11: =VLOOKUP(CONCATENATE(LEFT(E$7, 7), "hb", "NHS ", $B11), [0]!data_range, 5, FALSE) -> #REF! | F11: =VLOOKUP(CONCATENATE(LEFT(F$7, 7), "hb", "NHS ", $B11), [0]!data_range, 5, FALSE) -> #REF! | G11: =VLOOKUP(CONCATENATE(LEFT(G$7, 7), "hb", "NHS ", $B11), [0]!data_range, 5, FALSE) -> #REF! | H11: =VLOOKUP(CONCATENATE(LEFT(H$7, 7), "hb", "NHS ", $B11), [0]!data_range, 5, FALSE) -> #REF! | I11: =VLOOKUP(CONCATENATE(LEFT(I$7, 7), "hb", "NHS ", $B11), [0]!data_range, 5, FALSE) -> #REF! | J11: =VLOOKUP(CONCATENATE(LEFT(J$7, 7), "hb", "NHS ", $B11), [0]!data_range, 5, FALSE) -> #REF! | ... L11: =VLOOKUP(CONCATENATE(LEFT(L$7, 7), "hb", "NHS ", $B11), [0]!data_range, 5, FALSE) -> #REF!
B12: Forth Valley | C12: =VLOOKUP(CONCATENATE(LEFT(C$7, 7), "hb", "NHS ", $B12), [0]!data_range, 5, FALSE) -> #REF! | D12: =VLOOKUP(CONCATENATE(LEFT(D$7, 7), "hb", "NHS ", $B12), [0]!data_range, 5, FALSE) -> #REF! | E12: =VLOOKUP(CONCATENATE(LEFT(E$7, 7), "hb", "NHS ", $B12), [0]!data_range, 5, FALSE) -> #REF! | F12: =VLOOKUP(CONCATENATE(LEFT(F$7, 7), "hb", "NHS ", $B12), [0]!data_range, 5, FALSE) -> #REF! | G12: =VLOOKUP(CONCATENATE(LEFT(G$7, 7), "hb", "NHS ", $B12), [0]!data_range, 5, FALSE) -> #REF! | H12: =VLOOKUP(CONCATENATE(LEFT(H$7, 7), "hb", "NHS ", $B12), [0]!data_range, 5, FALSE) -> #REF! | I12: =VLOOKUP(CONCATENATE(LEFT(I$7, 7), "hb", "NHS ", $B12), [0]!data_range, 5, FALSE) -> #REF! | J12: =VLOOKUP(CONCATENATE(LEFT(J$7, 7), "hb", "NHS ", $B12), [0]!data_range, 5, FALSE) -> #REF! | ... L12: =VLOOKUP(CONCATENATE(LEFT(L$7, 7), "hb", "NHS ", $B12), [0]!data_range, 5, FALSE) -> #REF!
B13: Grampian | C13: =VLOOKUP(CONCATENATE(LEFT(C$7, 7), "hb", "NHS ", $B13), [0]!data_range, 5, FALSE) -> #REF! | D13: =VLOOKUP(CONCATENATE(LEFT(D$7, 7), "hb", "NHS ", $B13), [0]!data_range, 5, FALSE) -> #REF! | E13: =VLOOKUP(CONCATENATE(LEFT(E$7, 7), "hb", "NHS ", $B13), [0]!data_range, 5, FALSE) -> #REF! | F13: =VLOOKUP(CONCATENATE(LEFT(F$7, 7), "hb", "NHS ", $B13), [0]!data_range, 5, FALSE) -> #REF! | G13: =VLOOKUP(CONCATENATE(LEFT(G$7, 7), "hb", "NHS ", $B13), [0]!data_range, 5, FALSE) -> #REF! | H13: =VLOOKUP(CONCATENATE(LEFT(H$7, 7), "hb", "NHS ", $B13), [0]!data_range, 5, FALSE) -> #REF! | I13: =VLOOKUP(CONCATENATE(LEFT(I$7, 7), "hb", "NHS ", $B13), [0]!data_range, 5, FALSE) -> #REF! | J13: =VLOOKUP(CONCATENATE(LEFT(J$7, 7), "hb", "NHS ", $B13), [0]!data_range, 5, FALSE) -> #REF! | ... L13: =VLOOKUP(CONCATENATE(LEFT(L$7, 7), "hb", "NHS ", $B13), [0]!data_range, 5, FALSE) -> #REF!
B14: Greater Glasgow and Clyde | C14: =VLOOKUP(CONCATENATE(LEFT(C$7, 7), "hb", "NHS ", $B14), [0]!data_range, 5, FALSE) -> #REF! | D14: =VLOOKUP(CONCATENATE(LEFT(D$7, 7), "hb", "NHS ", $B14), [0]!data_range, 5, FALSE) -> #REF! | E14: =VLOOKUP(CONCATENATE(LEFT(E$7, 7), "hb", "NHS ", $B14), [0]!data_range, 5, FALSE) -> #REF! | F14: =VLOOKUP(CONCATENATE(LEFT(F$7, 7), "hb", "NHS ", $B14), [0]!data_range, 5, FALSE) -> #REF! | G14: =VLOOKUP(CONCATENATE(LEFT(G$7, 7), "hb", "NHS ", $B14), [0]!data_range, 5, FALSE) -> #REF! | H14: =VLOOKUP(CONCATENATE(LEFT(H$7, 7), "hb", "NHS ", $B14), [0]!data_range, 5, FALSE) -> #REF! | I14: =VLOOKUP(CONCATENATE(LEFT(I$7, 7), "hb", "NHS ", $B14), [0]!data_range, 5, FALSE) -> #REF! | J14: =VLOOKUP(CONCATENATE(LEFT(J$7, 7), "hb", "NHS ", $B14), [0]!data_range, 5, FALSE) -> #REF! | ... L14: =VLOOKUP(CONCATENATE(LEFT(L$7, 7), "hb", "NHS ", $B14), [0]!data_range, 5, FALSE) -> #REF!
B15: Highland | C15: =VLOOKUP(CONCATENATE(LEFT(C$7, 7), "hb", "NHS ", $B15), [0]!data_range, 5, FALSE) -> #REF! | D15: =VLOOKUP(CONCATENATE(LEFT(D$7, 7), "hb", "NHS ", $B15), [0]!data_range, 5, FALSE) -> #REF! | E15: =VLOOKUP(CONCATENATE(LEFT(E$7, 7), "hb", "NHS ", $B15), [0]!data_range, 5, FALSE) -> #REF! | F15: =VLOOKUP(CONCATENATE(LEFT(F$7, 7), "hb", "NHS ", $B15), [0]!data_range, 5, FALSE) -> #REF! | G15: =VLOOKUP(CONCATENATE(LEFT(G$7, 7), "hb", "NHS ", $B15), [0]!data_range, 5, FALSE) -> #REF! | H15: =VLOOKUP(CONCATENATE(LEFT(H$7, 7), "hb", "NHS ", $B15), [0]!data_range, 5, FALSE) -> #REF! | I15: =VLOOKUP(CONCATENATE(LEFT(I$7, 7), "hb", "NHS ", $B15), [0]!data_range, 5, FALSE) -> #REF! | J15: =VLOOKUP(CONCATENATE(LEFT(J$7, 7), "hb", "NHS ", $B15), [0]!data_range, 5, FALSE) -> #REF! | ... L15: =VLOOKUP(CONCATENATE(LEFT(L$7, 7), "hb", "NHS ", $B15), [0]!data_range, 5, FALSE) -> #REF!
B16: Lanarkshire | C16: =VLOOKUP(CONCATENATE(LEFT(C$7, 7), "hb", "NHS ", $B16), [0]!data_range, 5, FALSE) -> #REF! | D16: =VLOOKUP(CONCATENATE(LEFT(D$7, 7), "hb", "NHS ", $B16), [0]!data_range, 5, FALSE) -> #REF! | E16: =VLOOKUP(CONCATENATE(LEFT(E$7, 7), "hb", "NHS ", $B16), [0]!data_range, 5, FALSE) -> #REF! | F16: =VLOOKUP(CONCATENATE(LEFT(F$7, 7), "hb", "NHS ", $B16), [0]!data_range, 5, FALSE) -> #REF! | G16: =VLOOKUP(CONCATENATE(LEFT(G$7, 7), "hb", "NHS ", $B16), [0]!data_range, 5, FALSE) -> #REF! | H16: =VLOOKUP(CONCATENATE(LEFT(H$7, 7), "hb", "NHS ", $B16), [0]!data_range, 5, FALSE) -> #REF! | I16: =VLOOKUP(CONCATENATE(LEFT(I$7, 7), "hb", "NHS ", $B16), [0]!data_range, 5, FALSE) -> #REF! | J16: =VLOOKUP(CONCATENATE(LEFT(J$7, 7), "hb", "NHS ", $B16), [0]!data_range, 5, FALSE) -> #REF! | ... L16: =VLOOKUP(CONCATENATE(LEFT(L$7, 7), "hb", "NHS ", $B16), [0]!data_range, 5, FALSE) -> #REF!
B17: Lothian | C17: =VLOOKUP(CONCATENATE(LEFT(C$7, 7), "hb", "NHS ", $B17), [0]!data_range, 5, FALSE) -> #REF! | D17: =VLOOKUP(CONCATENATE(LEFT(D$7, 7), "hb", "NHS ", $B17), [0]!data_range, 5, FALSE) -> #REF! | E17: =VLOOKUP(CONCATENATE(LEFT(E$7, 7), "hb", "NHS ", $B17), [0]!data_range, 5, FALSE) -> #REF! | F17: =VLOOKUP(CONCATENATE(LEFT(F$7, 7), "hb", "NHS ", $B17), [0]!data_range, 5, FALSE) -> #REF! | G17: =VLOOKUP(CONCATENATE(LEFT(G$7, 7), "hb", "NHS ", $B17), [0]!data_range, 5, FALSE) -> #REF! | H17: =VLOOKUP(CONCATENATE(LEFT(H$7, 7), "hb", "NHS ", $B17), [0]!data_range, 5, FALSE) -> #REF! | I17: =VLOOKUP(CONCATENATE(LEFT(I$7, 7), "hb", "NHS ", $B17), [0]!data_range, 5, FALSE) -> #REF! | J17: =VLOOKUP(CONCATENATE(LEFT(J$7, 7), "hb", "NHS ", $B17), [0]!data_range, 5, FALSE) -> #REF! | ... L17: =VLOOKUP(CONCATENATE(LEFT(L$7, 7), "hb", "NHS ", $B17), [0]!data_range, 5, FALSE) -> #REF!
B18: Orkney | C18: =VLOOKUP(CONCATENATE(LEFT(C$7, 7), "hb", "NHS ", $B18), [0]!data_range, 5, FALSE) -> #REF! | D18: =VLOOKUP(CONCATENATE(LEFT(D$7, 7), "hb", "NHS ", $B18), [0]!data_range, 5, FALSE) -> #REF! | E18: =VLOOKUP(CONCATENATE(LEFT(E$7, 7), "hb", "NHS ", $B18), [0]!data_range, 5, FALSE) -> #REF! | F18: =VLOOKUP(CONCATENATE(LEFT(F$7, 7), "hb", "NHS ", $B18), [0]!data_range, 5, FALSE) -> #REF! | G18: =VLOOKUP(CONCATENATE(LEFT(G$7, 7), "hb", "NHS ", $B18), [0]!data_range, 5, FALSE) -> #REF! | H18: =VLOOKUP(CONCATENATE(LEFT(H$7, 7), "hb", "NHS ", $B18), [0]!data_range, 5, FALSE) -> #REF! | I18: =VLOOKUP(CONCATENATE(LEFT(I$7, 7), "hb", "NHS ", $B18), [0]!data_range, 5, FALSE) -> #REF! | J18: =VLOOKUP(CONCATENATE(LEFT(J$7, 7), "hb", "NHS ", $B18), [0]!data_range, 5, FALSE) -> #REF! | ... L18: =VLOOKUP(CONCATENATE(LEFT(L$7, 7), "hb", "NHS ", $B18), [0]!data_range, 5, FALSE) -> #REF!
B19: Shetland | C19: =VLOOKUP(CONCATENATE(LEFT(C$7, 7), "hb", "NHS ", $B19), [0]!data_range, 5, FALSE) -> #REF! | D19: =VLOOKUP(CONCATENATE(LEFT(D$7, 7), "hb", "NHS ", $B19), [0]!data_range, 5, FALSE) -> #REF! | E19: =VLOOKUP(CONCATENATE(LEFT(E$7, 7), "hb", "NHS ", $B19), [0]!data_range, 5, FALSE) -> #REF! | F19: =VLOOKUP(CONCATENATE(LEFT(F$7, 7), "hb", "NHS ", $B19), [0]!data_range, 5, FALSE) -> #REF! | G19: =VLOOKUP(CONCATENATE(LEFT(G$7, 7), "hb", "NHS ", $B19), [0]!data_range, 5, FALSE) -> #REF! | H19: =VLOOKUP(CONCATENATE(LEFT(H$7, 7), "hb", "NHS ", $B19), [0]!data_range, 5, FALSE) -> #REF! | I19: =VLOOKUP(CONCATENATE(LEFT(I$7, 7), "hb", "NHS ", $B19), [0]!data_range, 5, FALSE) -> #REF! | J19: =VLOOKUP(CONCATENATE(LEFT(J$7, 7), "hb", "NHS ", $B19), [0]!data_range, 5, FALSE) -> #REF! | ... L19: =VLOOKUP(CONCATENATE(LEFT(L$7, 7), "hb", "NHS ", $B19), [0]!data_range, 5, FALSE) -> #REF!
... B21: Western Isles | C21: =VLOOKUP(CONCATENATE(LEFT(C$7, 7), "hb", "NHS ", $B21), [0]!data_range, 5, FALSE) -> #REF! | D21: =VLOOKUP(CONCATENATE(LEFT(D$7, 7), "hb", "NHS ", $B21), [0]!data_range, 5, FALSE) -> #REF! | E21: =VLOOKUP(CONCATENATE(LEFT(E$7, 7), "hb", "NHS ", $B21), [0]!data_range, 5, FALSE) -> #REF! | F21: =VLOOKUP(CONCATENATE(LEFT(F$7, 7), "hb", "NHS ", $B21), [0]!data_range, 5, FALSE) -> #REF! | G21: =VLOOKUP(CONCATENATE(LEFT(G$7, 7), "hb", "NHS ", $B21), [0]!data_range, 5, FALSE) -> #REF! | H21: =VLOOKUP(CONCATENATE(LEFT(H$7, 7), "hb", "NHS ", $B21), [0]!data_range, 5, FALSE) -> #REF! | I21: =VLOOKUP(CONCATENATE(LEFT(I$7, 7), "hb", "NHS ", $B21), [0]!data_range, 5, FALSE) -> #REF! | J21: =VLOOKUP(CONCATENATE(LEFT(J$7, 7), "hb", "NHS ", $B21), [0]!data_range, 5, FALSE) -> #REF! | ... L21: =VLOOKUP(CONCATENATE(LEFT(L$7, 7), "hb", "NHS ", $B21), [0]!data_range, 5, FALSE) -> #REF!
B22: Scotland | C22: =VLOOKUP(CONCATENATE(LEFT(C$7, 7), "Scotland", $B22), [0]!data_range, 5, FALSE) -> #REF! | D22: =VLOOKUP(CONCATENATE(LEFT(D$7, 7), "Scotland", $B22), [0]!data_range, 5, FALSE) -> #REF! | E22: =VLOOKUP(CONCATENATE(LEFT(E$7, 7), "Scotland", $B22), [0]!data_range, 5, FALSE) -> #REF! | F22: =VLOOKUP(CONCATENATE(LEFT(F$7, 7), "Scotland", $B22), [0]!data_range, 5, FALSE) -> #REF! | G22: =VLOOKUP(CONCATENATE(LEFT(G$7, 7), "Scotland", $B22), [0]!data_range, 5, FALSE) -> #REF! | H22: =VLOOKUP(CONCATENATE(LEFT(H$7, 7), "Scotland", $B22), [0]!data_range, 5, FALSE) -> #REF! | I22: =VLOOKUP(CONCATENATE(LEFT(I$7, 7), "Scotland", $B22), [0]!data_range, 5, FALSE) -> #REF! | J22: =VLOOKUP(CONCATENATE(LEFT(J$7, 7), "Scotland", $B22), [0]!data_range, 5, FALSE) -> #REF! | ... L22: =VLOOKUP(CONCATENATE(LEFT(L$7, 7), "Scotland", $B22), [0]!data_range, 5, FALSE) -> #REF!
B24: External causes of death excluded from analysis
B26: Source: SMR01 (including GLS), SMR04 and NRS Death Records
B27: Health and Social Care Team, PHS
B28: ="p. " & calculation!$E$14 -> #REF!
B29: ="1. " & calculation!E17 -> 1. Figures in 2020/21 and 2021/22 are likely to have been affected by the impact of COVID-19 on hospital stays.

Sheet Figure A1-1 - HB
B2: Figure A1.1: Percentage of last six months of life spent at home or in a community setting
B3: ="by NHS Board of Residence; " & M8 -> by NHS Board of Residence; Scotland
A5: 1
N7: =calculation!B$10 -> #REF! | O7: =calculation!C$10 -> #REF! | P7: =calculation!D$10 -> #REF! | Q7: =calculation!E$10 -> #REF! | R7: =calculation!F$10 -> #REF! | S7: =calculation!G$10 -> #REF! | T7: =calculation!H$10 -> #REF! | U7: =calculation!I$10 -> #REF! | ... W7: =calculation!K$10 -> #REF!
M8: =VLOOKUP($A$5, calculation!$A$12:$B$26, 2, 0) -> Scotland | N8: =IF($M$8 = "Scotland", VLOOKUP(CONCATENATE(LEFT(N$7, 7), "Scotland", $M$8), [0]!data_range, 5, FALSE), VLOOKUP(CONCATENATE(LEFT(N$7, 7), "hb", "NHS ", $M$8), [0]!data_range, 5, FALSE)) -> #REF! | O8: =IF($M$8 = "Scotland", VLOOKUP(CONCATENATE(LEFT(O$7, 7), "Scotland", $M$8), [0]!data_range, 5, FALSE), VLOOKUP(CONCATENATE(LEFT(O$7, 7), "hb", "NHS ", $M$8), [0]!data_range, 5, FALSE)) -> #REF! | P8: =IF($M$8 = "Scotland", VLOOKUP(CONCATENATE(LEFT(P$7, 7), "Scotland", $M$8), [0]!data_range, 5, FALSE), VLOOKUP(CONCATENATE(LEFT(P$7, 7), "hb", "NHS ", $M$8), [0]!data_range, 5, FALSE)) -> #REF! | Q8: =IF($M$8 = "Scotland", VLOOKUP(CONCATENATE(LEFT(Q$7, 7), "Scotland", $M$8), [0]!data_range, 5, FALSE), VLOOKUP(CONCATENATE(LEFT(Q$7, 7), "hb", "NHS ", $M$8), [0]!data_range, 5, FALSE)) -> #REF! | R8: =IF($M$8 = "Scotland", VLOOKUP(CONCATENATE(LEFT(R$7, 7), "Scotland", $M$8), [0]!data_range, 5, FALSE), VLOOKUP(CONCATENATE(LEFT(R$7, 7), "hb", "NHS ", $M$8), [0]!data_range, 5, FALSE)) -> #REF! | S8: =IF($M$8 = "Scotland", VLOOKUP(CONCATENATE(LEFT(S$7, 7), "Scotland", $M$8), [0]!data_range, 5, FALSE), VLOOKUP(CONCATENATE(LEFT(S$7, 7), "hb", "NHS ", $M$8), [0]!data_range, 5, FALSE)) -> #REF! | T8: =IF($M$8 = "Scotland", VLOOKUP(CONCATENATE(LEFT(T$7, 7), "Scotland", $M$8), [0]!data_range, 5, FALSE), VLOOKUP(CONCATENATE(LEFT(T$7, 7), "hb", "NHS ", $M$8), [0]!data_range, 5, FALSE)) -> #REF! | U8: =IF($M$8 = "Scotland", VLOOKUP(CONCATENATE(LEFT(U$7, 7), "Scotland", $M$8), [0]!data_range, 5, FALSE), VLOOKUP(CONCATENATE(LEFT(U$7, 7), "hb", "NHS ", $M$8), [0]!data_range, 5, FALSE)) -> #REF! | ... W8: =IF($M$8 = "Scotland", VLOOKUP(CONCATENATE(LEFT(W$7, 7), "Scotland", $M$8), [0]!data_range, 5, FALSE), VLOOKUP(CONCATENATE(LEFT(W$7, 7), "hb", "NHS ", $M$8), [0]!data_range, 5, FALSE)) -> #REF!
B31: Please note that the y-axis does not start at zero.
B33: External causes of death excluded from analysis
B35: Source: SMR01 (including GLS), SMR04 and NRS Death Records
B36: Health and Social Care Team, PHS
B37: ="p. " & calculation!$E$14 -> #REF!
B38: ="1. " & calculation!E17 -> 1. Figures in 2020/21 and 2021/22 are likely to have been affected by the impact of COVID-19 on hospital stays.

Sheet Table 2 - HSCP
B1: =Notes!B1:O1
B2: Table 2: Percentage of last six months of life spent at home or in a community setting
B3: by Health and Social Care Partnership
L5: Financial Year Ending 31st March
B7: Health and Social Care Partnership | C7: =calculation!B$10 -> #REF! | D7: =calculation!C$10 -> #REF! | E7: =calculation!D$10 -> #REF! | F7: =calculation!E$10 -> #REF! | G7: =calculation!F$10 -> #REF! | H7: =calculation!G$10 -> #REF! | I7: =calculation!H$10 -> #REF! | J7: =calculation!I$10 -> #REF! | ... L7: =calculation!K$10 -> #REF!
B8: Aberdeen City | C8: =VLOOKUP(CONCATENATE(LEFT(C$7, 7), "hscp", $B8), [0]!data_range, 5, FALSE) -> #REF! | D8: =VLOOKUP(CONCATENATE(LEFT(D$7, 7), "hscp", $B8), [0]!data_range, 5, FALSE) -> #REF! | E8: =VLOOKUP(CONCATENATE(LEFT(E$7, 7), "hscp", $B8), [0]!data_range, 5, FALSE) -> #REF! | F8: =VLOOKUP(CONCATENATE(LEFT(F$7, 7), "hscp", $B8), [0]!data_range, 5, FALSE) -> #REF! | G8: =VLOOKUP(CONCATENATE(LEFT(G$7, 7), "hscp", $B8), [0]!data_range, 5, FALSE) -> #REF! | H8: =VLOOKUP(CONCATENATE(LEFT(H$7, 7), "hscp", $B8), [0]!data_range, 5, FALSE) -> #REF! | I8: =VLOOKUP(CONCATENATE(LEFT(I$7, 7), "hscp", $B8), [0]!data_range, 5, FALSE) -> #REF! | J8: =VLOOKUP(CONCATENATE(LEFT(J$7, 7), "hscp", $B8), [0]!data_range, 5, FALSE) -> #REF! | ... L8: =VLOOKUP(CONCATENATE(LEFT(L$7, 7), "hscp", $B8), [0]!data_range, 5, FALSE) -> #REF! | AA8: =R8=H8 -> #REF! | AB8: =S8=J8 -> #REF! | AC8: =T8=K8 -> #REF!
B9: Aberdeenshire | C9: =VLOOKUP(CONCATENATE(LEFT(C$7, 7), "hscp", $B9), [0]!data_range, 5, FALSE) -> #REF! | D9: =VLOOKUP(CONCATENATE(LEFT(D$7, 7), "hscp", $B9), [0]!data_range, 5, FALSE) -> #REF! | E9: =VLOOKUP(CONCATENATE(LEFT(E$7, 7), "hscp", $B9), [0]!data_range, 5, FALSE) -> #REF! | F9: =VLOOKUP(CONCATENATE(LEFT(F$7, 7), "hscp", $B9), [0]!data_range, 5, FALSE) -> #REF! | G9: =VLOOKUP(CONCATENATE(LEFT(G$7, 7), "hscp", $B9), [0]!data_range, 5, FALSE) -> #REF! | H9: =VLOOKUP(CONCATENATE(LEFT(H$7, 7), "hscp", $B9), [0]!data_range, 5, FALSE) -> #REF! | I9: =VLOOKUP(CONCATENATE(LEFT(I$7, 7), "hscp", $B9), [0]!data_range, 5, FALSE) -> #REF! | J9: =VLOOKUP(CONCATENATE(LEFT(J$7, 7), "hscp", $B9), [0]!data_range, 5, FALSE) -> #REF! | ... L9: =VLOOKUP(CONCATENATE(LEFT(L$7, 7), "hscp", $B9), [0]!data_range, 5, FALSE) -> #REF! | AA9: =R9=H9 -> #REF! | AB9: =S9=J9 -> #REF! | AC9: =T9=K9 -> #REF!
B10: Angus | C10: =VLOOKUP(CONCATENATE(LEFT(C$7, 7), "hscp", $B10), [0]!data_range, 5, FALSE) -> #REF! | D10: =VLOOKUP(CONCATENATE(LEFT(D$7, 7), "hscp", $B10), [0]!data_range, 5, FALSE) -> #REF! | E10: =VLOOKUP(CONCATENATE(LEFT(E$7, 7), "hscp", $B10), [0]!data_range, 5, FALSE) -> #REF! | F10: =VLOOKUP(CONCATENATE(LEFT(F$7, 7), "hscp", $B10), [0]!data_range, 5, FALSE) -> #REF! | G10: =VLOOKUP(CONCATENATE(LEFT(G$7, 7), "hscp", $B10), [0]!data_range, 5, FALSE) -> #REF! | H10: =VLOOKUP(CONCATENATE(LEFT(H$7, 7), "hscp", $B10), [0]!data_range, 5, FALSE) -> #REF! | I10: =VLOOKUP(CONCATENATE(LEFT(I$7, 7), "hscp", $B10), [0]!data_range, 5, FALSE) -> #REF! | J10: =VLOOKUP(CONCATENATE(LEFT(J$7, 7), "hscp", $B10), [0]!data_range, 5, FALSE) -> #REF! | ... L10: =VLOOKUP(CONCATENATE(LEFT(L$7, 7), "hscp", $B10), [0]!data_range, 5, FALSE) -> #REF! | AA10: =R10=H10 -> #REF! | AB10: =S10=J10 -> #REF! | AC10: =T10=K10 -> #REF!
B11: Argyll and Bute | C11: =VLOOKUP(CONCATENATE(LEFT(C$7, 7), "hscp", $B11), [0]!data_range, 5, FALSE) -> #REF! | D11: =VLOOKUP(CONCATENATE(LEFT(D$7, 7), "hscp", $B11), [0]!data_range, 5, FALSE) -> #REF! | E11: =VLOOKUP(CONCATENATE(LEFT(E$7, 7), "hscp", $B11), [0]!data_range, 5, FALSE) -> #REF! | F11: =VLOOKUP(CONCATENATE(LEFT(F$7, 7), "hscp", $B11), [0]!data_range, 5, FALSE) -> #REF! | G11: =VLOOKUP(CONCATENATE(LEFT(G$7, 7), "hscp", $B11), [0]!data_range, 5, FALSE) -> #REF! | H11: =VLOOKUP(CONCATENATE(LEFT(H$7, 7), "hscp", $B11), [0]!data_range, 5, FALSE) -> #REF! | I11: =VLOOKUP(CONCATENATE(LEFT(I$7, 7), "hscp", $B11), [0]!data_range, 5, FALSE) -> #REF! | J11: =VLOOKUP(CONCATENATE(LEFT(J$7, 7), "hscp", $B11), [0]!data_range, 5, FALSE) -> #REF! | ... L11: =VLOOKUP(CONCATENATE(LEFT(L$7, 7), "hscp", $B11), [0]!data_range, 5, FALSE) -> #REF! | AA11: =R11=H11 -> #REF! | AB11: =S11=J11 -> #REF! | AC11: =T11=K11 -> #REF!
B12: Clackmannanshire and Stirling | C12: =VLOOKUP(CONCATENATE(LEFT(C$7, 7), "hscp", $B12), [0]!data_range, 5, FALSE) -> #REF! | D12: =VLOOKUP(CONCATENATE(LEFT(D$7, 7), "hscp", $B12), [0]!data_range, 5, FALSE) -> #REF! | E12: =VLOOKUP(CONCATENATE(LEFT(E$7, 7), "hscp", $B12), [0]!data_range, 5, FALSE) -> #REF! | F12: =VLOOKUP(CONCATENATE(LEFT(F$7, 7), "hscp", $B12), [0]!data_range, 5, FALSE) -> #REF! | G12: =VLOOKUP(CONCATENATE(LEFT(G$7, 7), "hscp", $B12), [0]!data_range, 5, FALSE) -> #REF! | H12: =VLOOKUP(CONCATENATE(LEFT(H$7, 7), "hscp", $B12), [0]!data_range, 5, FALSE) -> #REF! | I12: =VLOOKUP(CONCATENATE(LEFT(I$7, 7), "hscp", $B12), [0]!data_range, 5, FALSE) -> #REF! | J12: =VLOOKUP(CONCATENATE(LEFT(J$7, 7), "hscp", $B12), [0]!data_range, 5, FALSE) -> #REF! | ... L12: =VLOOKUP(CONCATENATE(LEFT(L$7, 7), "hscp", $B12), [0]!data_range, 5, FALSE) -> #REF! | AA12: =R12=H12 -> #REF! | AB12: =S12=J12 -> #REF! | AC12: =T12=K12 -> #REF!
B13: Dumfries and Galloway | C13: =VLOOKUP(CONCATENATE(LEFT(C$7, 7), "hscp", $B13), [0]!data_range, 5, FALSE) -> #REF! | D13: =VLOOKUP(CONCATENATE(LEFT(D$7, 7), "hscp", $B13), [0]!data_range, 5, FALSE) -> #REF! | E13: =VLOOKUP(CONCATENATE(LEFT(E$7, 7), "hscp", $B13), [0]!data_range, 5, FALSE) -> #REF! | F13: =VLOOKUP(CONCATENATE(LEFT(F$7, 7), "hscp", $B13), [0]!data_range, 5, FALSE) -> #REF! | G13: =VLOOKUP(CONCATENATE(LEFT(G$7, 7), "hscp", $B13), [0]!data_range, 5, FALSE) -> #REF! | H13: =VLOOKUP(CONCATENATE(LEFT(H$7, 7), "hscp", $B13), [0]!data_range, 5, FALSE) -> #REF! | I13: =VLOOKUP(CONCATENATE(LEFT(I$7, 7), "hscp", $B13), [0]!data_range, 5, FALSE) -> #REF! | J13: =VLOOKUP(CONCATENATE(LEFT(J$7, 7), "hscp", $B13), [0]!data_range, 5, FALSE) -> #REF! | ... L13: =VLOOKUP(CONCATENATE(LEFT(L$7, 7), "hscp", $B13), [0]!data_range, 5, FALSE) -> #REF! | AA13: =R13=H13 -> #REF! | AB13: =S13=J13 -> #REF! | AC13: =T13=K13 -> #REF!
B14: Dundee City | C14: =VLOOKUP(CONCATENATE(LEFT(C$7, 7), "hscp", $B14), [0]!data_range, 5, FALSE) -> #REF! | D14: =VLOOKUP(CONCATENATE(LEFT(D$7, 7), "hscp", $B14), [0]!data_range, 5, FALSE) -> #REF! | E14: =VLOOKUP(CONCATENATE(LEFT(E$7, 7), "hscp", $B14), [0]!data_range, 5, FALSE) -> #REF! | F14: =VLOOKUP(CONCATENATE(LEFT(F$7, 7), "hscp", $B14), [0]!data_range, 5, FALSE) -> #REF! | G14: =VLOOKUP(CONCATENATE(LEFT(G$7, 7), "hscp", $B14), [0]!data_range, 5, FALSE) -> #REF! | H14: =VLOOKUP(CONCATENATE(LEFT(H$7, 7), "hscp", $B14), [0]!data_range, 5, FALSE) -> #REF! | I14: =VLOOKUP(CONCATENATE(LEFT(I$7, 7), "hscp", $B14), [0]!data_range, 5, FALSE) -> #REF! | J14: =VLOOKUP(CONCATENATE(LEFT(J$7, 7), "hscp", $B14), [0]!data_range, 5, FALSE) -> #REF! | ... L14: =VLOOKUP(CONCATENATE(LEFT(L$7, 7), "hscp", $B14), [0]!data_range, 5, FALSE) -> #REF! | AA14: =R14=H14 -> #REF! | AB14: =S14=J14 -> #REF! | AC14: =T14=K14 -> #REF!
B15: East Ayrshire | C15: =VLOOKUP(CONCATENATE(LEFT(C$7, 7), "hscp", $B15), [0]!data_range, 5, FALSE) -> #REF! | D15: =VLOOKUP(CONCATENATE(LEFT(D$7, 7), "hscp", $B15), [0]!data_range, 5, FALSE) -> #REF! | E15: =VLOOKUP(CONCATENATE(LEFT(E$7, 7), "hscp", $B15), [0]!data_range, 5, FALSE) -> #REF! | F15: =VLOOKUP(CONCATENATE(LEFT(F$7, 7), "hscp", $B15), [0]!data_range, 5, FALSE) -> #REF! | G15: =VLOOKUP(CONCATENATE(LEFT(G$7, 7), "hscp", $B15), [0]!data_range, 5, FALSE) -> #REF! | H15: =VLOOKUP(CONCATENATE(LEFT(H$7, 7), "hscp", $B15), [0]!data_range, 5, FALSE) -> #REF! | I15: =VLOOKUP(CONCATENATE(LEFT(I$7, 7), "hscp", $B15), [0]!data_range, 5, FALSE) -> #REF! | J15: =VLOOKUP(CONCATENATE(LEFT(J$7, 7), "hscp", $B15), [0]!data_range, 5, FALSE) -> #REF! | ... L15: =VLOOKUP(CONCATENATE(LEFT(L$7, 7), "hscp", $B15), [0]!data_range, 5, FALSE) -> #REF! | AA15: =R15=H15 -> #REF! | AB15: =S15=J15 -> #REF! | AC15: =T15=K15 -> #REF!
B16: East Dunbartonshire | C16: =VLOOKUP(CONCATENATE(LEFT(C$7, 7), "hscp", $B16), [0]!data_range, 5, FALSE) -> #REF! | D16: =VLOOKUP(CONCATENATE(LEFT(D$7, 7), "hscp", $B16), [0]!data_range, 5, FALSE) -> #REF! | E16: =VLOOKUP(CONCATENATE(LEFT(E$7, 7), "hscp", $B16), [0]!data_range, 5, FALSE) -> #REF! | F16: =VLOOKUP(CONCATENATE(LEFT(F$7, 7), "hscp", $B16), [0]!data_range, 5, FALSE) -> #REF! | G16: =VLOOKUP(CONCATENATE(LEFT(G$7, 7), "hscp", $B16), [0]!data_range, 5, FALSE) -> #REF! | H16: =VLOOKUP(CONCATENATE(LEFT(H$7, 7), "hscp", $B16), [0]!data_range, 5, FALSE) -> #REF! | I16: =VLOOKUP(CONCATENATE(LEFT(I$7, 7), "hscp", $B16), [0]!data_range, 5, FALSE) -> #REF! | J16: =VLOOKUP(CONCATENATE(LEFT(J$7, 7), "hscp", $B16), [0]!data_range, 5, FALSE) -> #REF! | ... L16: =VLOOKUP(CONCATENATE(LEFT(L$7, 7), "hscp", $B16), [0]!data_range, 5, FALSE) -> #REF! | AA16: =R16=H16 -> #REF! | AB16: =S16=J16 -> #REF! | AC16: =T16=K16 -> #REF!
B17: East Lothian | C17: =VLOOKUP(CONCATENATE(LEFT(C$7, 7), "hscp", $B17), [0]!data_range, 5, FALSE) -> #REF! | D17: =VLOOKUP(CONCATENATE(LEFT(D$7, 7), "hscp", $B17), [0]!data_range, 5, FALSE) -> #REF! | E17: =VLOOKUP(CONCATENATE(LEFT(E$7, 7), "hscp", $B17), [0]!data_range, 5, FALSE) -> #REF! | F17: =VLOOKUP(CONCATENATE(LEFT(F$7, 7), "hscp", $B17), [0]!data_range, 5, FALSE) -> #REF! | G17: =VLOOKUP(CONCATENATE(LEFT(G$7, 7), "hscp", $B17), [0]!data_range, 5, FALSE) -> #REF! | H17: =VLOOKUP(CONCATENATE(LEFT(H$7, 7), "hscp", $B17), [0]!data_range, 5, FALSE) -> #REF! | I17: =VLOOKUP(CONCATENATE(LEFT(I$7, 7), "hscp", $B17), [0]!data_range, 5, FALSE) -> #REF! | J17: =VLOOKUP(CONCATENATE(LEFT(J$7, 7), "hscp", $B17), [0]!data_range, 5, FALSE) -> #REF! | ... L17: =VLOOKUP(CONCATENATE(LEFT(L$7, 7), "hscp", $B17), [0]!data_range, 5, FALSE) -> #REF! | AA17: =R17=H17 -> #REF! | AB17: =S17=J17 -> #REF! | AC17: =T17=K17 -> #REF!
B18: East Renfrewshire | C18: =VLOOKUP(CONCATENATE(LEFT(C$7, 7), "hscp", $B18), [0]!data_range, 5, FALSE) -> #REF! | D18: =VLOOKUP(CONCATENATE(LEFT(D$7, 7), "hscp", $B18), [0]!data_range, 5, FALSE) -> #REF! | E18: =VLOOKUP(CONCATENATE(LEFT(E$7, 7), "hscp", $B18), [0]!data_range, 5, FALSE) -> #REF! | F18: =VLOOKUP(CONCATENATE(LEFT(F$7, 7), "hscp", $B18), [0]!data_range, 5, FALSE) -> #REF! | G18: =VLOOKUP(CONCATENATE(LEFT(G$7, 7), "hscp", $B18), [0]!data_range, 5, FALSE) -> #REF! | H18: =VLOOKUP(CONCATENATE(LEFT(H$7, 7), "hscp", $B18), [0]!data_range, 5, FALSE) -> #REF! | I18: =VLOOKUP(CONCATENATE(LEFT(I$7, 7), "hscp", $B18), [0]!data_range, 5, FALSE) -> #REF! | J18: =VLOOKUP(CONCATENATE(LEFT(J$7, 7), "hscp", $B18), [0]!data_range, 5, FALSE) -> #REF! | ... L18: =VLOOKUP(CONCATENATE(LEFT(L$7, 7), "hscp", $B18), [0]!data_range, 5, FALSE) -> #REF! | AA18: =R18=H18 -> #REF! | AB18: =S18=J18 -> #REF! | AC18: =T18=K18 -> #REF!
B19: Edinburgh | C19: =VLOOKUP(CONCATENATE(LEFT(C$7, 7), "hscp", $B19), [0]!data_range, 5, FALSE) -> #REF! | D19: =VLOOKUP(CONCATENATE(LEFT(D$7, 7), "hscp", $B19), [0]!data_range, 5, FALSE) -> #REF! | E19: =VLOOKUP(CONCATENATE(LEFT(E$7, 7), "hscp", $B19), [0]!data_range, 5, FALSE) -> #REF! | F19: =VLOOKUP(CONCATENATE(LEFT(F$7, 7), "hscp", $B19), [0]!data_range, 5, FALSE) -> #REF! | G19: =VLOOKUP(CONCATENATE(LEFT(G$7, 7), "hscp", $B19), [0]!data_range, 5, FALSE) -> #REF! | H19: =VLOOKUP(CONCATENATE(LEFT(H$7, 7), "hscp", $B19), [0]!data_range, 5, FALSE) -> #REF! | I19: =VLOOKUP(CONCATENATE(LEFT(I$7, 7), "hscp", $B19), [0]!data_range, 5, FALSE) -> #REF! | J19: =VLOOKUP(CONCATENATE(LEFT(J$7, 7), "hscp", $B19), [0]!data_range, 5, FALSE) -> #REF! | ... L19: =VLOOKUP(CONCATENATE(LEFT(L$7, 7), "hscp", $B19), [0]!data_range, 5, FALSE) -> #REF! | AA19: =R19=H19 -> #REF! | AB19: =S19=J19 -> #REF! | AC19: =T19=K19 -> #REF!
... B38: Western Isles | C38: =VLOOKUP(CONCATENATE(LEFT(C$7, 7), "hscp", $B38), [0]!data_range, 5, FALSE) -> #REF! | D38: =VLOOKUP(CONCATENATE(LEFT(D$7, 7), "hscp", $B38), [0]!data_range, 5, FALSE) -> #REF! | E38: =VLOOKUP(CONCATENATE(LEFT(E$7, 7), "hscp", $B38), [0]!data_range, 5, FALSE) -> #REF! | F38: =VLOOKUP(CONCATENATE(LEFT(F$7, 7), "hscp", $B38), [0]!data_range, 5, FALSE) -> #REF! | G38: =VLOOKUP(CONCATENATE(LEFT(G$7, 7), "hscp", $B38), [0]!data_range, 5, FALSE) -> #REF! | H38: =VLOOKUP(CONCATENATE(LEFT(H$7, 7), "hscp", $B38), [0]!data_range, 5, FALSE) -> #REF! | I38: =VLOOKUP(CONCATENATE(LEFT(I$7, 7), "hscp", $B38), [0]!data_range, 5, FALSE) -> #REF! | J38: =VLOOKUP(CONCATENATE(LEFT(J$7, 7), "hscp", $B38), [0]!data_range, 5, FALSE) -> #REF! | ... L38: =VLOOKUP(CONCATENATE(LEFT(L$7, 7), "hscp", $B38), [0]!data_range, 5, FALSE) -> #REF! | AA38: =R38=H38 -> #REF! | AB38: =S38=J38 -> #REF! | AC38: =T38=K38 -> #REF!
B39: Scotland | C39: =VLOOKUP(CONCATENATE(LEFT(C$7, 7), "Scotland", $B39), [0]!data_range, 5, FALSE) -> #REF! | D39: =VLOOKUP(CONCATENATE(LEFT(D$7, 7), "Scotland", $B39), [0]!data_range, 5, FALSE) -> #REF! | E39: =VLOOKUP(CONCATENATE(LEFT(E$7, 7), "Scotland", $B39), [0]!data_range, 5, FALSE) -> #REF! | F39: =VLOOKUP(CONCATENATE(LEFT(F$7, 7), "Scotland", $B39), [0]!data_range, 5, FALSE) -> #REF! | G39: =VLOOKUP(CONCATENATE(LEFT(G$7, 7), "Scotland", $B39), [0]!data_range, 5, FALSE) -> #REF! | H39: =VLOOKUP(CONCATENATE(LEFT(H$7, 7), "Scotland", $B39), [0]!data_range, 5, FALSE) -> #REF! | I39: =VLOOKUP(CONCATENATE(LEFT(I$7, 7), "Scotland", $B39), [0]!data_range, 5, FALSE) -> #REF! | J39: =VLOOKUP(CONCATENATE(LEFT(J$7, 7), "Scotland", $B39), [0]!data_range, 5, FALSE) -> #REF! | ... L39: =VLOOKUP(CONCATENATE(LEFT(L$7, 7), "Scotland", $B39), [0]!data_range, 5, FALSE) -> #REF! | AA39: =R39=H39 -> #REF! | AB39: =S39=J39 -> #REF! | AC39: =T39=K39 -> #REF!
B42: External causes of death excluded from analysis
B44: Source: SMR01 (including GLS), SMR04 and NRS Death Records
B45: Health and Social Care Team, PHS
B46: ="p. " & calculation!$E$14 -> #REF!
B47: ="1. " & calculation!E17 -> 1. Figures in 2020/21 and 2021/22 are likely to have been affected by the impact of COVID-19 on hospital stays.

Sheet Figure A1-2 - HSCP
B2: Figure A1.2: Percentage of last six months of life spent at home or in a community setting
B3: ="by Health and Social Care Partnership; " & M8 -> by Health and Social Care Partnership; Scotland
A5: 1
N7: =calculation!B$10 -> #REF! | O7: =calculation!C$10 -> #REF! | P7: =calculation!D$10 -> #REF! | Q7: =calculation!E$10 -> #REF! | R7: =calculation!F$10 -> #REF! | S7: =calculation!G$10 -> #REF! | T7: =calculation!H$10 -> #REF! | U7: =calculation!I$10 -> #REF! | ... W7: =calculation!K$10 -> #REF!
M8: =VLOOKUP($A$5, calculation!$A$28:$B$59, 2, 0) -> Scotland | N8: =IF($M$8 = "Scotland", VLOOKUP(CONCATENATE(LEFT(N$7, 7), "Scotland", $M$8), [0]!data_range, 5, FALSE), VLOOKUP(CONCATENATE(LEFT(N$7, 7), "hscp", $M$8), [0]!data_range, 5, FALSE)) -> #REF! | O8: =IF($M$8 = "Scotland", VLOOKUP(CONCATENATE(LEFT(O$7, 7), "Scotland", $M$8), [0]!data_range, 5, FALSE), VLOOKUP(CONCATENATE(LEFT(O$7, 7), "hscp", $M$8), [0]!data_range, 5, FALSE)) -> #REF! | P8: =IF($M$8 = "Scotland", VLOOKUP(CONCATENATE(LEFT(P$7, 7), "Scotland", $M$8), [0]!data_range, 5, FALSE), VLOOKUP(CONCATENATE(LEFT(P$7, 7), "hscp", $M$8), [0]!data_range, 5, FALSE)) -> #REF! | Q8: =IF($M$8 = "Scotland", VLOOKUP(CONCATENATE(LEFT(Q$7, 7), "Scotland", $M$8), [0]!data_range, 5, FALSE), VLOOKUP(CONCATENATE(LEFT(Q$7, 7), "hscp", $M$8), [0]!data_range, 5, FALSE)) -> #REF! | R8: =IF($M$8 = "Scotland", VLOOKUP(CONCATENATE(LEFT(R$7, 7), "Scotland", $M$8), [0]!data_range, 5, FALSE), VLOOKUP(CONCATENATE(LEFT(R$7, 7), "hscp", $M$8), [0]!data_range, 5, FALSE)) -> #REF! | S8: =IF($M$8 = "Scotland", VLOOKUP(CONCATENATE(LEFT(S$7, 7), "Scotland", $M$8), [0]!data_range, 5, FALSE), VLOOKUP(CONCATENATE(LEFT(S$7, 7), "hscp", $M$8), [0]!data_range, 5, FALSE)) -> #REF! | T8: =IF($M$8 = "Scotland", VLOOKUP(CONCATENATE(LEFT(T$7, 7), "Scotland", $M$8), [0]!data_range, 5, FALSE), VLOOKUP(CONCATENATE(LEFT(T$7, 7), "hscp", $M$8), [0]!data_range, 5, FALSE)) -> #REF! | U8: =IF($M$8 = "Scotland", VLOOKUP(CONCATENATE(LEFT(U$7, 7), "Scotland", $M$8), [0]!data_range, 5, FALSE), VLOOKUP(CONCATENATE(LEFT(U$7, 7), "hscp", $M$8), [0]!data_range, 5, FALSE)) -> #REF! | ... W8: =IF($M$8 = "Scotland", VLOOKUP(CONCATENATE(LEFT(W$7, 7), "Scotland", $M$8), [0]!data_range, 5, FALSE), VLOOKUP(CONCATENATE(LEFT(W$7, 7), "hscp", $M$8), [0]!data_range, 5, FALSE)) -> #REF!
B31: Please note that the y-axis does not start at zero.
B33: External causes of death excluded from analysis
B35: Source: SMR01 (including GLS), SMR04 and NRS Death Records
B36: Health and Social Care Team, PHS
B37: ="p. " & calculation!$E$14 -> #REF!
B38: ="1. " & calculation!E17 -> 1. Figures in 2020/21 and 2021/22 are likely to have been affected by the impact of COVID-19 on hospital stays.

Sheet Table 3 - Age Sex
B1: =Notes!B1:O1
B2: Table 3: Percentage of last six months of life spent at home or in a community setting
B3: by Age and Sex
M5: Financial Year Ending 31st March
B7: Age Group | C7: Sex | D7: =calculation!B$10 -> #REF! | E7: =calculation!C$10 -> #REF! | F7: =calculation!D$10 -> #REF! | G7: =calculation!E$10 -> #REF! | H7: =calculation!F$10 -> #REF! | I7: =calculation!G$10 -> #REF! | J7: =calculation!H$10 -> #REF! | K7: =calculation!I$10 -> #REF! | ... M7: =calculation!K$10 -> #REF!
B8: 0-17 | C8: Female | D8: =VLOOKUP(CONCATENATE(LEFT(D$7, 7), "age/sex", $B$8, " ", $C8), [0]!data_range, 5, FALSE) -> #REF! | E8: =VLOOKUP(CONCATENATE(LEFT(E$7, 7), "age/sex", $B$8, " ", $C8), [0]!data_range, 5, FALSE) -> #REF! | F8: =VLOOKUP(CONCATENATE(LEFT(F$7, 7), "age/sex", $B$8, " ", $C8), [0]!data_range, 5, FALSE) -> #REF! | G8: =VLOOKUP(CONCATENATE(LEFT(G$7, 7), "age/sex", $B$8, " ", $C8), [0]!data_range, 5, FALSE) -> #REF! | H8: =VLOOKUP(CONCATENATE(LEFT(H$7, 7), "age/sex", $B$8, " ", $C8), [0]!data_range, 5, FALSE) -> #REF! | I8: =VLOOKUP(CONCATENATE(LEFT(I$7, 7), "age/sex", $B$8, " ", $C8), [0]!data_range, 5, FALSE) -> #REF! | J8: =VLOOKUP(CONCATENATE(LEFT(J$7, 7), "age/sex", $B$8, " ", $C8), [0]!data_range, 5, FALSE) -> #REF! | K8: =VLOOKUP(CONCATENATE(LEFT(K$7, 7), "age/sex", $B$8, " ", $C8), [0]!data_range, 5, FALSE) -> #REF! | ... M8: =VLOOKUP(CONCATENATE(LEFT(M$7, 7), "age/sex", $B$8, " ", $C8), [0]!data_range, 5, FALSE) -> #REF!
C9: Male | D9: =VLOOKUP(CONCATENATE(LEFT(D$7, 7), "age/sex", $B$8, " ", $C9), [0]!data_range, 5, FALSE) -> #REF! | E9: =VLOOKUP(CONCATENATE(LEFT(E$7, 7), "age/sex", $B$8, " ", $C9), [0]!data_range, 5, FALSE) -> #REF! | F9: =VLOOKUP(CONCATENATE(LEFT(F$7, 7), "age/sex", $B$8, " ", $C9), [0]!data_range, 5, FALSE) -> #REF! | G9: =VLOOKUP(CONCATENATE(LEFT(G$7, 7), "age/sex", $B$8, " ", $C9), [0]!data_range, 5, FALSE) -> #REF! | H9: =VLOOKUP(CONCATENATE(LEFT(H$7, 7), "age/sex", $B$8, " ", $C9), [0]!data_range, 5, FALSE) -> #REF! | I9: =VLOOKUP(CONCATENATE(LEFT(I$7, 7), "age/sex", $B$8, " ", $C9), [0]!data_range, 5, FALSE) -> #REF! | J9: =VLOOKUP(CONCATENATE(LEFT(J$7, 7), "age/sex", $B$8, " ", $C9), [0]!data_range, 5, FALSE) -> #REF! | K9: =VLOOKUP(CONCATENATE(LEFT(K$7, 7), "age/sex", $B$8, " ", $C9), [0]!data_range, 5, FALSE) -> #REF! | ... M9: =VLOOKUP(CONCATENATE(LEFT(M$7, 7), "age/sex", $B$8, " ", $C9), [0]!data_range, 5, FALSE) -> #REF!
C10: Both | D10: =VLOOKUP(CONCATENATE(LEFT(D$7, 7), "age/sex", $B$8, " ", $C10), [0]!data_range, 5, FALSE) -> #REF! | E10: =VLOOKUP(CONCATENATE(LEFT(E$7, 7), "age/sex", $B$8, " ", $C10), [0]!data_range, 5, FALSE) -> #REF! | F10: =VLOOKUP(CONCATENATE(LEFT(F$7, 7), "age/sex", $B$8, " ", $C10), [0]!data_range, 5, FALSE) -> #REF! | G10: =VLOOKUP(CONCATENATE(LEFT(G$7, 7), "age/sex", $B$8, " ", $C10), [0]!data_range, 5, FALSE) -> #REF! | H10: =VLOOKUP(CONCATENATE(LEFT(H$7, 7), "age/sex", $B$8, " ", $C10), [0]!data_range, 5, FALSE) -> #REF! | I10: =VLOOKUP(CONCATENATE(LEFT(I$7, 7), "age/sex", $B$8, " ", $C10), [0]!data_range, 5, FALSE) -> #REF! | J10: =VLOOKUP(CONCATENATE(LEFT(J$7, 7), "age/sex", $B$8, " ", $C10), [0]!data_range, 5, FALSE) -> #REF! | K10: =VLOOKUP(CONCATENATE(LEFT(K$7, 7), "age/sex", $B$8, " ", $C10), [0]!data_range, 5, FALSE) -> #REF! | ... M10: =VLOOKUP(CONCATENATE(LEFT(M$7, 7), "age/sex", $B$8, " ", $C10), [0]!data_range, 5, FALSE) -> #REF!
B11: 18-44 | C11: Female | D11: =VLOOKUP(CONCATENATE(LEFT(D$7, 7), "age/sex", $B$11, " ", $C11), [0]!data_range, 5, FALSE) -> #REF! | E11: =VLOOKUP(CONCATENATE(LEFT(E$7, 7), "age/sex", $B$11, " ", $C11), [0]!data_range, 5, FALSE) -> #REF! | F11: =VLOOKUP(CONCATENATE(LEFT(F$7, 7), "age/sex", $B$11, " ", $C11), [0]!data_range, 5, FALSE) -> #REF! | G11: =VLOOKUP(CONCATENATE(LEFT(G$7, 7), "age/sex", $B$11, " ", $C11), [0]!data_range, 5, FALSE) -> #REF! | H11: =VLOOKUP(CONCATENATE(LEFT(H$7, 7), "age/sex", $B$11, " ", $C11), [0]!data_range, 5, FALSE) -> #REF! | I11: =VLOOKUP(CONCATENATE(LEFT(I$7, 7), "age/sex", $B$11, " ", $C11), [0]!data_range, 5, FALSE) -> #REF! | J11: =VLOOKUP(CONCATENATE(LEFT(J$7, 7), "age/sex", $B$11, " ", $C11), [0]!data_range, 5, FALSE) -> #REF! | K11: =VLOOKUP(CONCATENATE(LEFT(K$7, 7), "age/sex", $B$11, " ", $C11), [0]!data_range, 5, FALSE) -> #REF! | ... M11: =VLOOKUP(CONCATENATE(LEFT(M$7, 7), "age/sex", $B$11, " ", $C11), [0]!data_range, 5, FALSE) -> #REF!
C12: Male | D12: =VLOOKUP(CONCATENATE(LEFT(D$7, 7), "age/sex", $B$11, " ", $C12), [0]!data_range, 5, FALSE) -> #REF! | E12: =VLOOKUP(CONCATENATE(LEFT(E$7, 7), "age/sex", $B$11, " ", $C12), [0]!data_range, 5, FALSE) -> #REF! | F12: =VLOOKUP(CONCATENATE(LEFT(F$7, 7), "age/sex", $B$11, " ", $C12), [0]!data_range, 5, FALSE) -> #REF! | G12: =VLOOKUP(CONCATENATE(LEFT(G$7, 7), "age/sex", $B$11, " ", $C12), [0]!data_range, 5, FALSE) -> #REF! | H12: =VLOOKUP(CONCATENATE(LEFT(H$7, 7), "age/sex", $B$11, " ", $C12), [0]!data_range, 5, FALSE) -> #REF! | I12: =VLOOKUP(CONCATENATE(LEFT(I$7, 7), "age/sex", $B$11, " ", $C12), [0]!data_range, 5, FALSE) -> #REF! | J12: =VLOOKUP(CONCATENATE(LEFT(J$7, 7), "age/sex", $B$11, " ", $C12), [0]!data_range, 5, FALSE) -> #REF! | K12: =VLOOKUP(CONCATENATE(LEFT(K$7, 7), "age/sex", $B$11, " ", $C12), [0]!data_range, 5, FALSE) -> #REF! | ... M12: =VLOOKUP(CONCATENATE(LEFT(M$7, 7), "age/sex", $B$11, " ", $C12), [0]!data_range, 5, FALSE) -> #REF!
C13: Both | D13: =VLOOKUP(CONCATENATE(LEFT(D$7, 7), "age/sex", $B$11, " ", $C13), [0]!data_range, 5, FALSE) -> #REF! | E13: =VLOOKUP(CONCATENATE(LEFT(E$7, 7), "age/sex", $B$11, " ", $C13), [0]!data_range, 5, FALSE) -> #REF! | F13: =VLOOKUP(CONCATENATE(LEFT(F$7, 7), "age/sex", $B$11, " ", $C13), [0]!data_range, 5, FALSE) -> #REF! | G13: =VLOOKUP(CONCATENATE(LEFT(G$7, 7), "age/sex", $B$11, " ", $C13), [0]!data_range, 5, FALSE) -> #REF! | H13: =VLOOKUP(CONCATENATE(LEFT(H$7, 7), "age/sex", $B$11, " ", $C13), [0]!data_range, 5, FALSE) -> #REF! | I13: =VLOOKUP(CONCATENATE(LEFT(I$7, 7), "age/sex", $B$11, " ", $C13), [0]!data_range, 5, FALSE) -> #REF! | J13: =VLOOKUP(CONCATENATE(LEFT(J$7, 7), "age/sex", $B$11, " ", $C13), [0]!data_range, 5, FALSE) -> #REF! | K13: =VLOOKUP(CONCATENATE(LEFT(K$7, 7), "age/sex", $B$11, " ", $C13), [0]!data_range, 5, FALSE) -> #REF! | ... M13: =VLOOKUP(CONCATENATE(LEFT(M$7, 7), "age/sex", $B$11, " ", $C13), [0]!data_range, 5, FALSE) -> #REF!
B14: 45-54 | C14: Female | D14: =VLOOKUP(CONCATENATE(LEFT(D$7, 7), "age/sex", $B$14, " ", $C14), [0]!data_range, 5, FALSE) -> #REF! | E14: =VLOOKUP(CONCATENATE(LEFT(E$7, 7), "age/sex", $B$14, " ", $C14), [0]!data_range, 5, FALSE) -> #REF! | F14: =VLOOKUP(CONCATENATE(LEFT(F$7, 7), "age/sex", $B$14, " ", $C14), [0]!data_range, 5, FALSE) -> #REF! | G14: =VLOOKUP(CONCATENATE(LEFT(G$7, 7), "age/sex", $B$14, " ", $C14), [0]!data_range, 5, FALSE) -> #REF! | H14: =VLOOKUP(CONCATENATE(LEFT(H$7, 7), "age/sex", $B$14, " ", $C14), [0]!data_range, 5, FALSE) -> #REF! | I14: =VLOOKUP(CONCATENATE(LEFT(I$7, 7), "age/sex", $B$14, " ", $C14), [0]!data_range, 5, FALSE) -> #REF! | J14: =VLOOKUP(CONCATENATE(LEFT(J$7, 7), "age/sex", $B$14, " ", $C14), [0]!data_range, 5, FALSE) -> #REF! | K14: =VLOOKUP(CONCATENATE(LEFT(K$7, 7), "age/sex", $B$14, " ", $C14), [0]!data_range, 5, FALSE) -> #REF! | ... M14: =VLOOKUP(CONCATENATE(LEFT(M$7, 7), "age/sex", $B$14, " ", $C14), [0]!data_range, 5, FALSE) -> #REF!
C15: Male | D15: =VLOOKUP(CONCATENATE(LEFT(D$7, 7), "age/sex", $B$14, " ", $C15), [0]!data_range, 5, FALSE) -> #REF! | E15: =VLOOKUP(CONCATENATE(LEFT(E$7, 7), "age/sex", $B$14, " ", $C15), [0]!data_range, 5, FALSE) -> #REF! | F15: =VLOOKUP(CONCATENATE(LEFT(F$7, 7), "age/sex", $B$14, " ", $C15), [0]!data_range, 5, FALSE) -> #REF! | G15: =VLOOKUP(CONCATENATE(LEFT(G$7, 7), "age/sex", $B$14, " ", $C15), [0]!data_range, 5, FALSE) -> #REF! | H15: =VLOOKUP(CONCATENATE(LEFT(H$7, 7), "age/sex", $B$14, " ", $C15), [0]!data_range, 5, FALSE) -> #REF! | I15: =VLOOKUP(CONCATENATE(LEFT(I$7, 7), "age/sex", $B$14, " ", $C15), [0]!data_range, 5, FALSE) -> #REF! | J15: =VLOOKUP(CONCATENATE(LEFT(J$7, 7), "age/sex", $B$14, " ", $C15), [0]!data_range, 5, FALSE) -> #REF! | K15: =VLOOKUP(CONCATENATE(LEFT(K$7, 7), "age/sex", $B$14, " ", $C15), [0]!data_range, 5, FALSE) -> #REF! | ... M15: =VLOOKUP(CONCATENATE(LEFT(M$7, 7), "age/sex", $B$14, " ", $C15), [0]!data_range, 5, FALSE) -> #REF!
C16: Both | D16: =VLOOKUP(CONCATENATE(LEFT(D$7, 7), "age/sex", $B$14, " ", $C16), [0]!data_range, 5, FALSE) -> #REF! | E16: =VLOOKUP(CONCATENATE(LEFT(E$7, 7), "age/sex", $B$14, " ", $C16), [0]!data_range, 5, FALSE) -> #REF! | F16: =VLOOKUP(CONCATENATE(LEFT(F$7, 7), "age/sex", $B$14, " ", $C16), [0]!data_range, 5, FALSE) -> #REF! | G16: =VLOOKUP(CONCATENATE(LEFT(G$7, 7), "age/sex", $B$14, " ", $C16), [0]!data_range, 5, FALSE) -> #REF! | H16: =VLOOKUP(CONCATENATE(LEFT(H$7, 7), "age/sex", $B$14, " ", $C16), [0]!data_range, 5, FALSE) -> #REF! | I16: =VLOOKUP(CONCATENATE(LEFT(I$7, 7), "age/sex", $B$14, " ", $C16), [0]!data_range, 5, FALSE) -> #REF! | J16: =VLOOKUP(CONCATENATE(LEFT(J$7, 7), "age/sex", $B$14, " ", $C16), [0]!data_range, 5, FALSE) -> #REF! | K16: =VLOOKUP(CONCATENATE(LEFT(K$7, 7), "age/sex", $B$14, " ", $C16), [0]!data_range, 5, FALSE) -> #REF! | ... M16: =VLOOKUP(CONCATENATE(LEFT(M$7, 7), "age/sex", $B$14, " ", $C16), [0]!data_range, 5, FALSE) -> #REF!
B17: 55-64 | C17: Female | D17: =VLOOKUP(CONCATENATE(LEFT(D$7, 7), "age/sex", $B$17, " ", $C17), [0]!data_range, 5, FALSE) -> #REF! | E17: =VLOOKUP(CONCATENATE(LEFT(E$7, 7), "age/sex", $B$17, " ", $C17), [0]!data_range, 5, FALSE) -> #REF! | F17: =VLOOKUP(CONCATENATE(LEFT(F$7, 7), "age/sex", $B$17, " ", $C17), [0]!data_range, 5, FALSE) -> #REF! | G17: =VLOOKUP(CONCATENATE(LEFT(G$7, 7), "age/sex", $B$17, " ", $C17), [0]!data_range, 5, FALSE) -> #REF! | H17: =VLOOKUP(CONCATENATE(LEFT(H$7, 7), "age/sex", $B$17, " ", $C17), [0]!data_range, 5, FALSE) -> #REF! | I17: =VLOOKUP(CONCATENATE(LEFT(I$7, 7), "age/sex", $B$17, " ", $C17), [0]!data_range, 5, FALSE) -> #REF! | J17: =VLOOKUP(CONCATENATE(LEFT(J$7, 7), "age/sex", $B$17, " ", $C17), [0]!data_range, 5, FALSE) -> #REF! | K17: =VLOOKUP(CONCATENATE(LEFT(K$7, 7), "age/sex", $B$17, " ", $C17), [0]!data_range, 5, FALSE) -> #REF! | ... M17: =VLOOKUP(CONCATENATE(LEFT(M$7, 7), "age/sex", $B$17, " ", $C17), [0]!data_range, 5, FALSE) -> #REF!
C18: Male | D18: =VLOOKUP(CONCATENATE(LEFT(D$7, 7), "age/sex", $B$17, " ", $C18), [0]!data_range, 5, FALSE) -> #REF! | E18: =VLOOKUP(CONCATENATE(LEFT(E$7, 7), "age/sex", $B$17, " ", $C18), [0]!data_range, 5, FALSE) -> #REF! | F18: =VLOOKUP(CONCATENATE(LEFT(F$7, 7), "age/sex", $B$17, " ", $C18), [0]!data_range, 5, FALSE) -> #REF! | G18: =VLOOKUP(CONCATENATE(LEFT(G$7, 7), "age/sex", $B$17, " ", $C18), [0]!data_range, 5, FALSE) -> #REF! | H18: =VLOOKUP(CONCATENATE(LEFT(H$7, 7), "age/sex", $B$17, " ", $C18), [0]!data_range, 5, FALSE) -> #REF! | I18: =VLOOKUP(CONCATENATE(LEFT(I$7, 7), "age/sex", $B$17, " ", $C18), [0]!data_range, 5, FALSE) -> #REF! | J18: =VLOOKUP(CONCATENATE(LEFT(J$7, 7), "age/sex", $B$17, " ", $C18), [0]!data_range, 5, FALSE) -> #REF! | K18: =VLOOKUP(CONCATENATE(LEFT(K$7, 7), "age/sex", $B$17, " ", $C18), [0]!data_range, 5, FALSE) -> #REF! | ... M18: =VLOOKUP(CONCATENATE(LEFT(M$7, 7), "age/sex", $B$17, " ", $C18), [0]!data_range, 5, FALSE) -> #REF!
C19: Both | D19: =VLOOKUP(CONCATENATE(LEFT(D$7, 7), "age/sex", $B$17, " ", $C19), [0]!data_range, 5, FALSE) -> #REF! | E19: =VLOOKUP(CONCATENATE(LEFT(E$7, 7), "age/sex", $B$17, " ", $C19), [0]!data_range, 5, FALSE) -> #REF! | F19: =VLOOKUP(CONCATENATE(LEFT(F$7, 7), "age/sex", $B$17, " ", $C19), [0]!data_range, 5, FALSE) -> #REF! | G19: =VLOOKUP(CONCATENATE(LEFT(G$7, 7), "age/sex", $B$17, " ", $C19), [0]!data_range, 5, FALSE) -> #REF! | H19: =VLOOKUP(CONCATENATE(LEFT(H$7, 7), "age/sex", $B$17, " ", $C19), [0]!data_range, 5, FALSE) -> #REF! | I19: =VLOOKUP(CONCATENATE(LEFT(I$7, 7), "age/sex", $B$17, " ", $C19), [0]!data_range, 5, FALSE) -> #REF! | J19: =VLOOKUP(CONCATENATE(LEFT(J$7, 7), "age/sex", $B$17, " ", $C19), [0]!data_range, 5, FALSE) -> #REF! | K19: =VLOOKUP(CONCATENATE(LEFT(K$7, 7), "age/sex", $B$17, " ", $C19), [0]!data_range, 5, FALSE) -> #REF! | ... M19: =VLOOKUP(CONCATENATE(LEFT(M$7, 7), "age/sex", $B$17, " ", $C19), [0]!data_range, 5, FALSE) -> #REF!
B20: 65-74 | C20: Female | D20: =VLOOKUP(CONCATENATE(LEFT(D$7, 7), "age/sex", $B$20, " ", $C20), [0]!data_range, 5, FALSE) -> #REF! | E20: =VLOOKUP(CONCATENATE(LEFT(E$7, 7), "age/sex", $B$20, " ", $C20), [0]!data_range, 5, FALSE) -> #REF! | F20: =VLOOKUP(CONCATENATE(LEFT(F$7, 7), "age/sex", $B$20, " ", $C20), [0]!data_range, 5, FALSE) -> #REF! | G20: =VLOOKUP(CONCATENATE(LEFT(G$7, 7), "age/sex", $B$20, " ", $C20), [0]!data_range, 5, FALSE) -> #REF! | H20: =VLOOKUP(CONCATENATE(LEFT(H$7, 7), "age/sex", $B$20, " ", $C20), [0]!data_range, 5, FALSE) -> #REF! | I20: =VLOOKUP(CONCATENATE(LEFT(I$7, 7), "age/sex", $B$20, " ", $C20), [0]!data_range, 5, FALSE) -> #REF! | J20: =VLOOKUP(CONCATENATE(LEFT(J$7, 7), "age/sex", $B$20, " ", $C20), [0]!data_range, 5, FALSE) -> #REF! | K20: =VLOOKUP(CONCATENATE(LEFT(K$7, 7), "age/sex", $B$20, " ", $C20), [0]!data_range, 5, FALSE) -> #REF! | ... M20: =VLOOKUP(CONCATENATE(LEFT(M$7, 7), "age/sex", $B$20, " ", $C20), [0]!data_range, 5, FALSE) -> #REF!
C21: Male | D21: =VLOOKUP(CONCATENATE(LEFT(D$7, 7), "age/sex", $B$20, " ", $C21), [0]!data_range, 5, FALSE) -> #REF! | E21: =VLOOKUP(CONCATENATE(LEFT(E$7, 7), "age/sex", $B$20, " ", $C21), [0]!data_range, 5, FALSE) -> #REF! | F21: =VLOOKUP(CONCATENATE(LEFT(F$7, 7), "age/sex", $B$20, " ", $C21), [0]!data_range, 5, FALSE) -> #REF! | G21: =VLOOKUP(CONCATENATE(LEFT(G$7, 7), "age/sex", $B$20, " ", $C21), [0]!data_range, 5, FALSE) -> #REF! | H21: =VLOOKUP(CONCATENATE(LEFT(H$7, 7), "age/sex", $B$20, " ", $C21), [0]!data_range, 5, FALSE) -> #REF! | I21: =VLOOKUP(CONCATENATE(LEFT(I$7, 7), "age/sex", $B$20, " ", $C21), [0]!data_range, 5, FALSE) -> #REF! | J21: =VLOOKUP(CONCATENATE(LEFT(J$7, 7), "age/sex", $B$20, " ", $C21), [0]!data_range, 5, FALSE) -> #REF! | K21: =VLOOKUP(CONCATENATE(LEFT(K$7, 7), "age/sex", $B$20, " ", $C21), [0]!data_range, 5, FALSE) -> #REF! | ... M21: =VLOOKUP(CONCATENATE(LEFT(M$7, 7), "age/sex", $B$20, " ", $C21), [0]!data_range, 5, FALSE) -> #REF!
C22: Both | D22: =VLOOKUP(CONCATENATE(LEFT(D$7, 7), "age/sex", $B$20, " ", $C22), [0]!data_range, 5, FALSE) -> #REF! | E22: =VLOOKUP(CONCATENATE(LEFT(E$7, 7), "age/sex", $B$20, " ", $C22), [0]!data_range, 5, FALSE) -> #REF! | F22: =VLOOKUP(CONCATENATE(LEFT(F$7, 7), "age/sex", $B$20, " ", $C22), [0]!data_range, 5, FALSE) -> #REF! | G22: =VLOOKUP(CONCATENATE(LEFT(G$7, 7), "age/sex", $B$20, " ", $C22), [0]!data_range, 5, FALSE) -> #REF! | H22: =VLOOKUP(CONCATENATE(LEFT(H$7, 7), "age/sex", $B$20, " ", $C22), [0]!data_range, 5, FALSE) -> #REF! | I22: =VLOOKUP(CONCATENATE(LEFT(I$7, 7), "age/sex", $B$20, " ", $C22), [0]!data_range, 5, FALSE) -> #REF! | J22: =VLOOKUP(CONCATENATE(LEFT(J$7, 7), "age/sex", $B$20, " ", $C22), [0]!data_range, 5, FALSE) -> #REF! | K22: =VLOOKUP(CONCATENATE(LEFT(K$7, 7), "age/sex", $B$20, " ", $C22), [0]!data_range, 5, FALSE) -> #REF! | ... M22: =VLOOKUP(CONCATENATE(LEFT(M$7, 7), "age/sex", $B$20, " ", $C22), [0]!data_range, 5, FALSE) -> #REF!
B23: 75-84 | C23: Female | D23: =VLOOKUP(CONCATENATE(LEFT(D$7, 7), "age/sex", $B$23, " ", $C23), [0]!data_range, 5, FALSE) -> #REF! | E23: =VLOOKUP(CONCATENATE(LEFT(E$7, 7), "age/sex", $B$23, " ", $C23), [0]!data_range, 5, FALSE) -> #REF! | F23: =VLOOKUP(CONCATENATE(LEFT(F$7, 7), "age/sex", $B$23, " ", $C23), [0]!data_range, 5, FALSE) -> #REF! | G23: =VLOOKUP(CONCATENATE(LEFT(G$7, 7), "age/sex", $B$23, " ", $C23), [0]!data_range, 5, FALSE) -> #REF! | H23: =VLOOKUP(CONCATENATE(LEFT(H$7, 7), "age/sex", $B$23, " ", $C23), [0]!data_range, 5, FALSE) -> #REF! | I23: =VLOOKUP(CONCATENATE(LEFT(I$7, 7), "age/sex", $B$23, " ", $C23), [0]!data_range, 5, FALSE) -> #REF! | J23: =VLOOKUP(CONCATENATE(LEFT(J$7, 7), "age/sex", $B$23, " ", $C23), [0]!data_range, 5, FALSE) -> #REF! | K23: =VLOOKUP(CONCATENATE(LEFT(K$7, 7), "age/sex", $B$23, " ", $C23), [0]!data_range, 5, FALSE) -> #REF! | ... M23: =VLOOKUP(CONCATENATE(LEFT(M$7, 7), "age/sex", $B$23, " ", $C23), [0]!data_range, 5, FALSE) -> #REF!
C24: Male | D24: =VLOOKUP(CONCATENATE(LEFT(D$7, 7), "age/sex", $B$23, " ", $C24), [0]!data_range, 5, FALSE) -> #REF! | E24: =VLOOKUP(CONCATENATE(LEFT(E$7, 7), "age/sex", $B$23, " ", $C24), [0]!data_range, 5, FALSE) -> #REF! | F24: =VLOOKUP(CONCATENATE(LEFT(F$7, 7), "age/sex", $B$23, " ", $C24), [0]!data_range, 5, FALSE) -> #REF! | G24: =VLOOKUP(CONCATENATE(LEFT(G$7, 7), "age/sex", $B$23, " ", $C24), [0]!data_range, 5, FALSE) -> #REF! | H24: =VLOOKUP(CONCATENATE(LEFT(H$7, 7), "age/sex", $B$23, " ", $C24), [0]!data_range, 5, FALSE) -> #REF! | I24: =VLOOKUP(CONCATENATE(LEFT(I$7, 7), "age/sex", $B$23, " ", $C24), [0]!data_range, 5, FALSE) -> #REF! | J24: =VLOOKUP(CONCATENATE(LEFT(J$7, 7), "age/sex", $B$23, " ", $C24), [0]!data_range, 5, FALSE) -> #REF! | K24: =VLOOKUP(CONCATENATE(LEFT(K$7, 7), "age/sex", $B$23, " ", $C24), [0]!data_range, 5, FALSE) -> #REF! | ... M24: =VLOOKUP(CONCATENATE(LEFT(M$7, 7), "age/sex", $B$23, " ", $C24), [0]!data_range, 5, FALSE) -> #REF!
C25: Both | D25: =VLOOKUP(CONCATENATE(LEFT(D$7, 7), "age/sex", $B$23, " ", $C25), [0]!data_range, 5, FALSE) -> #REF! | E25: =VLOOKUP(CONCATENATE(LEFT(E$7, 7), "age/sex", $B$23, " ", $C25), [0]!data_range, 5, FALSE) -> #REF! | F25: =VLOOKUP(CONCATENATE(LEFT(F$7, 7), "age/sex", $B$23, " ", $C25), [0]!data_range, 5, FALSE) -> #REF! | G25: =VLOOKUP(CONCATENATE(LEFT(G$7, 7), "age/sex", $B$23, " ", $C25), [0]!data_range, 5, FALSE) -> #REF! | H25: =VLOOKUP(CONCATENATE(LEFT(H$7, 7), "age/sex", $B$23, " ", $C25), [0]!data_range, 5, FALSE) -> #REF! | I25: =VLOOKUP(CONCATENATE(LEFT(I$7, 7), "age/sex", $B$23, " ", $C25), [0]!data_range, 5, FALSE) -> #REF! | J25: =VLOOKUP(CONCATENATE(LEFT(J$7, 7), "age/sex", $B$23, " ", $C25), [0]!data_range, 5, FALSE) -> #REF! | K25: =VLOOKUP(CONCATENATE(LEFT(K$7, 7), "age/sex", $B$23, " ", $C25), [0]!data_range, 5, FALSE) -> #REF! | ... M25: =VLOOKUP(CONCATENATE(LEFT(M$7, 7), "age/sex", $B$23, " ", $C25), [0]!data_range, 5, FALSE) -> #REF!
B26: 85+ | C26: Female | D26: =VLOOKUP(CONCATENATE(LEFT(D$7, 7), "age/sex", $B$26, " ", $C26), [0]!data_range, 5, FALSE) -> #REF! | E26: =VLOOKUP(CONCATENATE(LEFT(E$7, 7), "age/sex", $B$26, " ", $C26), [0]!data_range, 5, FALSE) -> #REF! | F26: =VLOOKUP(CONCATENATE(LEFT(F$7, 7), "age/sex", $B$26, " ", $C26), [0]!data_range, 5, FALSE) -> #REF! | G26: =VLOOKUP(CONCATENATE(LEFT(G$7, 7), "age/sex", $B$26, " ", $C26), [0]!data_range, 5, FALSE) -> #REF! | H26: =VLOOKUP(CONCATENATE(LEFT(H$7, 7), "age/sex", $B$26, " ", $C26), [0]!data_range, 5, FALSE) -> #REF! | I26: =VLOOKUP(CONCATENATE(LEFT(I$7, 7), "age/sex", $B$26, " ", $C26), [0]!data_range, 5, FALSE) -> #REF! | J26: =VLOOKUP(CONCATENATE(LEFT(J$7, 7), "age/sex", $B$26, " ", $C26), [0]!data_range, 5, FALSE) -> #REF! | K26: =VLOOKUP(CONCATENATE(LEFT(K$7, 7), "age/sex", $B$26, " ", $C26), [0]!data_range, 5, FALSE) -> #REF! | ... M26: =VLOOKUP(CONCATENATE(LEFT(M$7, 7), "age/sex", $B$26, " ", $C26), [0]!data_range, 5, FALSE) -> #REF!
C27: Male | D27: =VLOOKUP(CONCATENATE(LEFT(D$7, 7), "age/sex", $B$26, " ", $C27), [0]!data_range, 5, FALSE) -> #REF! | E27: =VLOOKUP(CONCATENATE(LEFT(E$7, 7), "age/sex", $B$26, " ", $C27), [0]!data_range, 5, FALSE) -> #REF! | F27: =VLOOKUP(CONCATENATE(LEFT(F$7, 7), "age/sex", $B$26, " ", $C27), [0]!data_range, 5, FALSE) -> #REF! | G27: =VLOOKUP(CONCATENATE(LEFT(G$7, 7), "age/sex", $B$26, " ", $C27), [0]!data_range, 5, FALSE) -> #REF! | H27: =VLOOKUP(CONCATENATE(LEFT(H$7, 7), "age/sex", $B$26, " ", $C27), [0]!data_range, 5, FALSE) -> #REF! | I27: =VLOOKUP(CONCATENATE(LEFT(I$7, 7), "age/sex", $B$26, " ", $C27), [0]!data_range, 5, FALSE) -> #REF! | J27: =VLOOKUP(CONCATENATE(LEFT(J$7, 7), "age/sex", $B$26, " ", $C27), [0]!data_range, 5, FALSE) -> #REF! | K27: =VLOOKUP(CONCATENATE(LEFT(K$7, 7), "age/sex", $B$26, " ", $C27), [0]!data_range, 5, FALSE) -> #REF! | ... M27: =VLOOKUP(CONCATENATE(LEFT(M$7, 7), "age/sex", $B$26, " ", $C27), [0]!data_range, 5, FALSE) -> #REF!
C28: Both | D28: =VLOOKUP(CONCATENATE(LEFT(D$7, 7), "age/sex", $B$26, " ", $C28), [0]!data_range, 5, FALSE) -> #REF! | E28: =VLOOKUP(CONCATENATE(LEFT(E$7, 7), "age/sex", $B$26, " ", $C28), [0]!data_range, 5, FALSE) -> #REF! | F28: =VLOOKUP(CONCATENATE(LEFT(F$7, 7), "age/sex", $B$26, " ", $C28), [0]!data_range, 5, FALSE) -> #REF! | G28: =VLOOKUP(CONCATENATE(LEFT(G$7, 7), "age/sex", $B$26, " ", $C28), [0]!data_range, 5, FALSE) -> #REF! | H28: =VLOOKUP(CONCATENATE(LEFT(H$7, 7), "age/sex", $B$26, " ", $C28), [0]!data_range, 5, FALSE) -> #REF! | I28: =VLOOKUP(CONCATENATE(LEFT(I$7, 7), "age/sex", $B$26, " ", $C28), [0]!data_range, 5, FALSE) -> #REF! | J28: =VLOOKUP(CONCATENATE(LEFT(J$7, 7), "age/sex", $B$26, " ", $C28), [0]!data_range, 5, FALSE) -> #REF! | K28: =VLOOKUP(CONCATENATE(LEFT(K$7, 7), "age/sex", $B$26, " ", $C28), [0]!data_range, 5, FALSE) -> #REF! | ... M28: =VLOOKUP(CONCATENATE(LEFT(M$7, 7), "age/sex", $B$26, " ", $C28), [0]!data_range, 5, FALSE) -> #REF!
B29: All Ages | C29: Female | D29: =VLOOKUP(CONCATENATE(LEFT(D$7, 7), "age/sex", $B$29, " ", $C29), [0]!data_range, 5, FALSE) -> #REF! | E29: =VLOOKUP(CONCATENATE(LEFT(E$7, 7), "age/sex", $B$29, " ", $C29), [0]!data_range, 5, FALSE) -> #REF! | F29: =VLOOKUP(CONCATENATE(LEFT(F$7, 7), "age/sex", $B$29, " ", $C29), [0]!data_range, 5, FALSE) -> #REF! | G29: =VLOOKUP(CONCATENATE(LEFT(G$7, 7), "age/sex", $B$29, " ", $C29), [0]!data_range, 5, FALSE) -> #REF! | H29: =VLOOKUP(CONCATENATE(LEFT(H$7, 7), "age/sex", $B$29, " ", $C29), [0]!data_range, 5, FALSE) -> #REF! | I29: =VLOOKUP(CONCATENATE(LEFT(I$7, 7), "age/sex", $B$29, " ", $C29), [0]!data_range, 5, FALSE) -> #REF! | J29: =VLOOKUP(CONCATENATE(LEFT(J$7, 7), "age/sex", $B$29, " ", $C29), [0]!data_range, 5, FALSE) -> #REF! | K29: =VLOOKUP(CONCATENATE(LEFT(K$7, 7), "age/sex", $B$29, " ", $C29), [0]!data_range, 5, FALSE) -> #REF! | ... M29: =VLOOKUP(CONCATENATE(LEFT(M$7, 7), "age/sex", $B$29, " ", $C29), [0]!data_range, 5, FALSE) -> #REF!
